2021-10-16 13:41:07,764 -  nornir.core -     INFO -        run() - Running task 'pull_vars' with args {} on 3 hosts
2021-10-20 10:57:07,761 -  nornir.core -     INFO -        run() - Running task 'pull_vars' with args {} on 3 hosts
2021-10-20 10:57:10,985 - nornir.core.task -    ERROR -      start() - Host 'R3': task 'send_configs' failed with traceback:
Traceback (most recent call last):
  File "/home/ggb/Desktop/CI-CD/lib/python3.8/site-packages/nornir/core/task.py", line 99, in start
    r = self.task(self, **self.params)
  File "/home/ggb/Desktop/CI-CD/lib/python3.8/site-packages/nornir_scrapli/tasks/core/send_configs.py", line 58, in send_configs
    scrapli_conn = task.host.get_connection("scrapli", task.nornir.config)
  File "/home/ggb/Desktop/CI-CD/lib/python3.8/site-packages/nornir/core/inventory.py", line 494, in get_connection
    self.open_connection(
  File "/home/ggb/Desktop/CI-CD/lib/python3.8/site-packages/nornir/core/inventory.py", line 546, in open_connection
    conn_obj.open(
  File "/home/ggb/Desktop/CI-CD/lib/python3.8/site-packages/nornir_scrapli/connection.py", line 98, in open
    connection.open()
  File "/home/ggb/Desktop/CI-CD/lib/python3.8/site-packages/scrapli/driver/base/sync_driver.py", line 86, in open
    self.channel.channel_authenticate_ssh(
  File "/home/ggb/Desktop/CI-CD/lib/python3.8/site-packages/scrapli/decorators.py", line 276, in decorate
    return self._multiprocessing_timeout(
  File "/home/ggb/Desktop/CI-CD/lib/python3.8/site-packages/scrapli/decorators.py", line 337, in _multiprocessing_timeout
    return future.result()
  File "/usr/lib/python3.8/concurrent/futures/_base.py", line 437, in result
    return self.__get_result()
  File "/usr/lib/python3.8/concurrent/futures/_base.py", line 389, in __get_result
    raise self._exception
  File "/usr/lib/python3.8/concurrent/futures/thread.py", line 57, in run
    result = self.fn(*self.args, **self.kwargs)
  File "/home/ggb/Desktop/CI-CD/lib/python3.8/site-packages/scrapli/channel/sync_channel.py", line 291, in channel_authenticate_ssh
    self._ssh_message_handler(output=authenticate_buf)
  File "/home/ggb/Desktop/CI-CD/lib/python3.8/site-packages/scrapli/channel/base_channel.py", line 280, in _ssh_message_handler
    raise ScrapliAuthenticationFailed(msg)
scrapli.exceptions.ScrapliAuthenticationFailed: No route to host

2021-10-20 10:57:10,986 - nornir.core.task -    ERROR -      start() - Host 'R2': task 'send_configs' failed with traceback:
Traceback (most recent call last):
  File "/home/ggb/Desktop/CI-CD/lib/python3.8/site-packages/nornir/core/task.py", line 99, in start
    r = self.task(self, **self.params)
  File "/home/ggb/Desktop/CI-CD/lib/python3.8/site-packages/nornir_scrapli/tasks/core/send_configs.py", line 58, in send_configs
    scrapli_conn = task.host.get_connection("scrapli", task.nornir.config)
  File "/home/ggb/Desktop/CI-CD/lib/python3.8/site-packages/nornir/core/inventory.py", line 494, in get_connection
    self.open_connection(
  File "/home/ggb/Desktop/CI-CD/lib/python3.8/site-packages/nornir/core/inventory.py", line 546, in open_connection
    conn_obj.open(
  File "/home/ggb/Desktop/CI-CD/lib/python3.8/site-packages/nornir_scrapli/connection.py", line 98, in open
    connection.open()
  File "/home/ggb/Desktop/CI-CD/lib/python3.8/site-packages/scrapli/driver/base/sync_driver.py", line 86, in open
    self.channel.channel_authenticate_ssh(
  File "/home/ggb/Desktop/CI-CD/lib/python3.8/site-packages/scrapli/decorators.py", line 276, in decorate
    return self._multiprocessing_timeout(
  File "/home/ggb/Desktop/CI-CD/lib/python3.8/site-packages/scrapli/decorators.py", line 337, in _multiprocessing_timeout
    return future.result()
  File "/usr/lib/python3.8/concurrent/futures/_base.py", line 437, in result
    return self.__get_result()
  File "/usr/lib/python3.8/concurrent/futures/_base.py", line 389, in __get_result
    raise self._exception
  File "/usr/lib/python3.8/concurrent/futures/thread.py", line 57, in run
    result = self.fn(*self.args, **self.kwargs)
  File "/home/ggb/Desktop/CI-CD/lib/python3.8/site-packages/scrapli/channel/sync_channel.py", line 291, in channel_authenticate_ssh
    self._ssh_message_handler(output=authenticate_buf)
  File "/home/ggb/Desktop/CI-CD/lib/python3.8/site-packages/scrapli/channel/base_channel.py", line 280, in _ssh_message_handler
    raise ScrapliAuthenticationFailed(msg)
scrapli.exceptions.ScrapliAuthenticationFailed: No route to host

2021-10-20 10:57:10,986 - nornir.core.task -    ERROR -      start() - Host 'R3': task 'pull_vars' failed with traceback:
Traceback (most recent call last):
  File "/home/ggb/Desktop/CI-CD/lib/python3.8/site-packages/nornir/core/task.py", line 99, in start
    r = self.task(self, **self.params)
  File "ospf-jinja2.py", line 14, in pull_vars
    push_config(task)
  File "ospf-jinja2.py", line 19, in push_config
    task.run(task=send_configs, configs=configurations)
  File "/home/ggb/Desktop/CI-CD/lib/python3.8/site-packages/nornir/core/task.py", line 174, in run
    raise NornirSubTaskError(task=run_task, result=r)
nornir.core.exceptions.NornirSubTaskError: Subtask: send_configs (failed)


2021-10-20 10:57:10,986 - nornir.core.task -    ERROR -      start() - Host 'R1': task 'send_configs' failed with traceback:
Traceback (most recent call last):
  File "/home/ggb/Desktop/CI-CD/lib/python3.8/site-packages/nornir/core/task.py", line 99, in start
    r = self.task(self, **self.params)
  File "/home/ggb/Desktop/CI-CD/lib/python3.8/site-packages/nornir_scrapli/tasks/core/send_configs.py", line 58, in send_configs
    scrapli_conn = task.host.get_connection("scrapli", task.nornir.config)
  File "/home/ggb/Desktop/CI-CD/lib/python3.8/site-packages/nornir/core/inventory.py", line 494, in get_connection
    self.open_connection(
  File "/home/ggb/Desktop/CI-CD/lib/python3.8/site-packages/nornir/core/inventory.py", line 546, in open_connection
    conn_obj.open(
  File "/home/ggb/Desktop/CI-CD/lib/python3.8/site-packages/nornir_scrapli/connection.py", line 98, in open
    connection.open()
  File "/home/ggb/Desktop/CI-CD/lib/python3.8/site-packages/scrapli/driver/base/sync_driver.py", line 86, in open
    self.channel.channel_authenticate_ssh(
  File "/home/ggb/Desktop/CI-CD/lib/python3.8/site-packages/scrapli/decorators.py", line 276, in decorate
    return self._multiprocessing_timeout(
  File "/home/ggb/Desktop/CI-CD/lib/python3.8/site-packages/scrapli/decorators.py", line 337, in _multiprocessing_timeout
    return future.result()
  File "/usr/lib/python3.8/concurrent/futures/_base.py", line 437, in result
    return self.__get_result()
  File "/usr/lib/python3.8/concurrent/futures/_base.py", line 389, in __get_result
    raise self._exception
  File "/usr/lib/python3.8/concurrent/futures/thread.py", line 57, in run
    result = self.fn(*self.args, **self.kwargs)
  File "/home/ggb/Desktop/CI-CD/lib/python3.8/site-packages/scrapli/channel/sync_channel.py", line 291, in channel_authenticate_ssh
    self._ssh_message_handler(output=authenticate_buf)
  File "/home/ggb/Desktop/CI-CD/lib/python3.8/site-packages/scrapli/channel/base_channel.py", line 280, in _ssh_message_handler
    raise ScrapliAuthenticationFailed(msg)
scrapli.exceptions.ScrapliAuthenticationFailed: No route to host

2021-10-20 10:57:10,987 - nornir.core.task -    ERROR -      start() - Host 'R1': task 'pull_vars' failed with traceback:
Traceback (most recent call last):
  File "/home/ggb/Desktop/CI-CD/lib/python3.8/site-packages/nornir/core/task.py", line 99, in start
    r = self.task(self, **self.params)
  File "ospf-jinja2.py", line 14, in pull_vars
    push_config(task)
  File "ospf-jinja2.py", line 19, in push_config
    task.run(task=send_configs, configs=configurations)
  File "/home/ggb/Desktop/CI-CD/lib/python3.8/site-packages/nornir/core/task.py", line 174, in run
    raise NornirSubTaskError(task=run_task, result=r)
nornir.core.exceptions.NornirSubTaskError: Subtask: send_configs (failed)


2021-10-20 10:57:10,987 - nornir.core.task -    ERROR -      start() - Host 'R2': task 'pull_vars' failed with traceback:
Traceback (most recent call last):
  File "/home/ggb/Desktop/CI-CD/lib/python3.8/site-packages/nornir/core/task.py", line 99, in start
    r = self.task(self, **self.params)
  File "ospf-jinja2.py", line 14, in pull_vars
    push_config(task)
  File "ospf-jinja2.py", line 19, in push_config
    task.run(task=send_configs, configs=configurations)
  File "/home/ggb/Desktop/CI-CD/lib/python3.8/site-packages/nornir/core/task.py", line 174, in run
    raise NornirSubTaskError(task=run_task, result=r)
nornir.core.exceptions.NornirSubTaskError: Subtask: send_configs (failed)


2021-10-20 10:59:08,368 -  nornir.core -     INFO -        run() - Running task 'pull_vars' with args {} on 3 hosts
